Workbook

Sheet Apresentação
B1: Você precisa fazer uma cópia da planilha para conseguir utilizar. Clique em "Arquivo → Fazer uma cópia" e salve sua versão para começar a editar.
B5: Planilha - Controle mensal de verba em mídia paga
B6: Utilize esta planilha para gerenciar a verba mensal investida nas suas ações de mídia paga. Preencha as informações necessárias e receba automaticamente a projeção de Leads e Vendas.
B8: O que você irá encontrar na planilha:
B10: Visibilidade da divisão de verba | G10: Tenha em um único lugar qual a sua divisão completa de verba para mídia paga.
B11: Previsibilidade de resultados | G11: Com o preenchimento da divisão de verba e os custos, a planilha já te apresenta uma previsão de Leads gerados e vendas realizadas.
B12: Acompanhamento das principais métricas | G12: Identifique automaticamente qual o CAC e o ROI, as principais métricas para acomparnhar os resultados da sua estratégia de mídia paga.
B13: Quanto de verba falta alocar | G13: De acordo com a verba mensal definida e o valor investido para cada mídia, você consegue identificar quanto ainda tem disponível para investir.
B15: Passo a passo para utilizar a planilha:
B17: 1. Verba mensal e Ticket Médio | G17: O primeiro passo é preencher qual o valor (em R$) da sua verba mensal de mídia paga e qual o Ticket Médio do seu produto ou serviço.
B18: 2. Previsão de Alocação por estratégia | G18: Distribuindo entre as estratégias de Tofu, Mofu e Bofu, a planilha ajuda a identificar se a sua verba está ultrapassando o percentual definido.
B19: 3. Divisão da Verba por mídia ou estratégia | G19: Faça a alocação de verba para cada tipo de mídia e estratégia, preenchendo os valores em R$.
B20: 4. Custo por Lead por mídia ou estratégia | G20: Informe qual é o seu custo de geração de Leads (CPL) para cada tipo de mídia e estratégia.
B21: 5. % de Lead → Vendas por mídia e por estratégia | G21: Preencha qual o percentual de conversão dos Leads gerados para vendas, de acordo com cada mídia e estratégia.
B23: Atenção → | G23: Os números já preenchidos são meramente ilustrativos. Substitua pelos dados corretos da sua empresa!
B24: Faça o seu controle mensal! | G24: Duplique a aba de Controle de Verba para fazer o controle mês a mês.
B26: Ficou com dúvida sobre algum termo ou sobre a importância de acompanhar cada um desses dados? Acesse os materiais de apoio!

Sheet Materiais de Apoio
B4: Materiais de Apoio
B5: Confira uma lista de materiais e conteúdos que vão ajudar você a entender sobre planejamento, as principais métricas e as melhores estratégias para mídia paga!
B7: Métricas de mídia paga:
B9: =HYPERLINK("https://resultadosdigitais.com.br/blog/o-que-e-custo-de-aquisicao-de-clientes/?utm_source=planilha&utm_medium=referral&utm_campaign=br-inb-materiais-planilha-launch-planilha_controle_de_verba_em_midia_paga","Tudo sobre o Custo de Aquisição de Clientes: o que é, como calcular e como otimizar o CAC de sua empresa") -> Tudo sobre o Custo de Aquisição de Clientes: o que é, como calcular e como otimizar o CAC de sua empresa
B10: =HYPERLINK("https://resultadosdigitais.com.br/blog/o-que-e-cpc-cpm-cpa/?utm_source=planilha&utm_medium=referral&utm_campaign=br-inb-materiais-planilha-launch-planilha_controle_de_verba_em_midia_paga","Entenda o que é Custo por Clique (CPC), Custo por Mil (CPM) e Custo por Aquisição (CPA) e aprenda a calcular cada uma das métricas") -> Entenda o que é Custo por Clique (CPC), Custo por Mil (CPM) e Custo por Aquisição (CPA) e aprenda a calcular cada uma das métricas
B11: =HYPERLINK("https://resultadosdigitais.com.br/blog/o-que-e-roi-retorno-sobre-investimento/?utm_source=planilha&utm_medium=referral&utm_campaign=br-inb-materiais-planilha-launch-planilha_controle_de_verba_em_midia_paga","ROI: o que é, como e por que calcular o Retorno sobre o Investimento") -> ROI: o que é, como e por que calcular o Retorno sobre o Investimento
B12: =HYPERLINK("https://resultadosdigitais.com.br/blog/ticket-medio/?utm_source=planilha&utm_medium=referral&utm_campaign=br-inb-materiais-planilha-launch-planilha_controle_de_verba_em_midia_paga","O que é e como aumentar o ticket médio na sua empresa") -> O que é e como aumentar o ticket médio na sua empresa
B13: =HYPERLINK("https://resultadosdigitais.com.br/blog/metricas-de-marketing/?utm_source=planilha&utm_medium=referral&utm_campaign=br-inb-materiais-planilha-launch-planilha_controle_de_verba_em_midia_paga","Quais métricas de marketing realmente medem o sucesso do meu negócio?") -> Quais métricas de marketing realmente medem o sucesso do meu negócio?
B15: Planejamento e estratégias para mídia paga:
B17: =HYPERLINK("https://resultadosdigitais.com.br/blog/o-que-e-tofu-mofu-bofu/?utm_source=planilha&utm_medium=referral&utm_campaign=br-inb-materiais-planilha-launch-planilha_controle_de_verba_em_midia_paga","O que é Topo de Funil (ToFu), Meio de Funil (MoFu) e Fundo de Funil (BoFu)") -> O que é Topo de Funil (ToFu), Meio de Funil (MoFu) e Fundo de Funil (BoFu)
B18: =HYPERLINK("https://resultadosdigitais.com.br/blog/canais-midia-paga/?utm_source=planilha&utm_medium=referral&utm_campaign=br-inb-materiais-planilha-launch-planilha_controle_de_verba_em_midia_paga","Conheça os principais canais de mídia paga em que você pode investir") -> Conheça os principais canais de mídia paga em que você pode investir
B19: =HYPERLINK("http://materiais.resultadosdigitais.com.br/midia-paga-inbound-marketing-v","[eBook + Checklist] Guia da Mídia Paga para Inbound Marketing") -> [eBook + Checklist] Guia da Mídia Paga para Inbound Marketing
B20: =HYPERLINK("https://materiais.resultadosdigitais.com.br/kit-analise-e-planejamento-mkt-digital/?utm_source=planilha&utm_medium=referral&utm_campaign=br-inb-materiais-planilha-launch-planilha_controle_de_verba_em_midia_paga","[Kit] Análise e Planejamento de Marketing Digital") -> [Kit] Análise e Planejamento de Marketing Digital
B22: Ferramentas para melhorar seus resultados de Marketing e Vendas:
B24: RD Station Marketing → A ferramenta tudo em um para gerenciar e automatizar suas ações de Marketing Digital
B25: =HYPERLINK("https://materiais.resultadosdigitais.com.br/novo-bate-papo-hr-crm?utm_source=planilha&utm_medium=referral&utm_campaign=br-inb-materiais-planilha-launch-planilha_controle_de_verba_em_midia_paga","RD Station CRM → Controle seu processo comercial e aumente vendas usando o novo CRM") -> RD Station CRM → Controle seu processo comercial e aumente vendas usando o novo CRM

Sheet Controle de Verba - MÊSANO
A1: CONTROLE DE VERBA EM MÍDIA PAGA | MÊS/ANO
E5: Valor Automático
A6: Qual a sua Verba Mensal de Mídia Paga? | B6: 300000 | D6: Falta Alocar | E6: =B6-SUM(B19:D25) -> 0
A7: Qual é o seu Ticket Médio? | B7: 1000
B9: Valor Automático | D9: Previsão de Alocação por estratégia
A10: Previsão do nº de Leads gerados com essa alocação | B10: =SUMPRODUCT(1/B32:D38,B19:D25) -> 79328.571 | D10: ToFu | E10: 0.3 | F10: {=TRANSPOSE(B26:D26)} -> 90000 | G10: =E10*B6 -> 90000
A11: Previsão de Vendas com essa alocação | B11: =SUMPRODUCT(1/B32:D38,B19:D25,B45:D51) -> 1060.1429 | D11: MoFu | E11: 0.4 | F11: 120000 | G11: =E11*B6 -> 120000
A12: CAC | B12: =B6/B11 -> 282.98073 | D12: BoFu | E12: 0.3 | F12: 90000 | G12: =E12*B6 -> 90000
A13: ROI | B13: =B7*B11/B6 -> 3.5338095
A16: Divisão da Verba por mídia e estratégia
A17: Preencha no quadro abaixo qual o valor investido para cada tipo de mídia e estratégia
B18: ToFu | C18: MoFu | D18: BoFu
A19: Facebook + Instagram | B19: 10000 | C19: 0 | D19: 0
A20: Google Pesquisa | B20: 20000 | C20: 0 | D20: 0
A21: Google Display | B21: 0 | C21: 0 | D21: 0 | E21: ← Altere os valores de acordo com seus investimentos
A22: Youtube | B22: 10000 | C22: 0 | D22: 0
A23: LinkedIn | B23: 50000 | C23: 120000 | D23: 90000
A24: Outras mídias | B24: 0 | C24: 0 | D24: 0
A25: Outras mídias | B25: 0 | C25: 0 | D25: 0
A26: Total | B26: =SUM(B19:B25) -> 90000 | C26: =SUM(C19:C25) -> 120000 | D26: =SUM(D19:D25) -> 90000
A29: Custo por Lead (CPL) por mídia e estratégia
A30: Preencha no quadro abaixo qual é o seu custo para cada Lead gerado por tipo de mídia e estratégia
B31: ToFu | C31: MoFu | D31: BoFu
A32: Facebook + Instagram | B32: 2 | C32: 18 | D32: 500
A33: Google Pesquisa | B33: 10 | C33: 20 | D33: 600 | E33: ← Altere os valores de acordo com seu CPL Obs.: Os valores devem ser diferentes de 0
A34: Google Display | B34: 8 | C34: 14 | D34: 200
A35: Youtube | B35: 7 | C35: 13 | D35: 300
A36: LinkedIn | B36: 1 | C36: 6 | D36: 100
A37: Outras mídias | B37: 1 | C37: 1 | D37: 1
A38: Outras mídias | B38: 1 | C38: 1 | D38: 1
A41: % de Lead → Vendas por mídia e por estratégia
A42: Preencha qual o percentual de conversão dos Leads gerados para Vendas por tipo de mídia e estratégia
A43: Obs.: Para calcular, é só dividir o nº de Vendas pelo nº de Leads (Ex.: 1000 leads → 50 vendas = 5%)
B44: ToFu | C44: MoFu | D44: BoFu
A45: Facebook + Instagram | B45: 0.017 | C45: 0.03 | D45: 0.1
A46: Google Pesquisa | B46: 0.02 | C46: 0.04 | D46: 0.25
A47: Google Display | B47: 0.011 | C47: 0.03 | D47: 0.14 | E47: ← Altere de acordo com sua taxa de conversão
A48: Youtube | B48: 0.012 | C48: 0.03 | D48: 0.2
A49: LinkedIn | B49: 0.01 | C49: 0.02 | D49: 0.02
A50: Outras mídias | B50: 0 | C50: 0 | D50: 0
...

Sheet __Solver__
A1: 2020191581277350428 | D1: upQdmYodiu9agjC | J1: 1
A2: =Max('Controle de Verba - MÊSANO'!B10) -> 79328.571 | B2: =Max(ProductMix_Example!F13) -> #REF!
A3: ='Controle de Verba - MÊSANO'!B19:D23 -> #VALUE! | B3: =ProductMix_Example!B3:D3 -> #REF!
A4: OSA= | B4: OSA=
B5: RV5hVF1pX1VFRBVRS1tvRV5hVF1qQ1RFRAlRS1pvRV5hU1h1XFRFRBVR
A6: RENj | B6: RkE=
A7: ='Controle de Verba - MÊSANO'!F10:F12 <= 'Controle de Verba - MÊSANO'!G10:G12 -> #VALUE! | B7: =ProductMix_Example!B3:D3 <= 0 -> #REF!
A8: ='Controle de Verba - MÊSANO'!B19:D23 <= 0 -> #VALUE! | B8: =ProductMix_Example!F7:F11 <= ProductMix_Example!G7:G11 -> #REF!
A9: ='Controle de Verba - MÊSANO'!E6 <= 0 -> TRUE

Sheet __Solver___conflict1022534816

Sheet __Solver___conflict1140783061
